Workbook

Sheet 1 - Outreach
A1: ALIF AGENCY - OUTREACH TRACKER - Weekly + Daily Activity
A2: TARGETS | E2: 300+ emails/wk | F2: >35% open | G2: >5% reply | H2: >3% pos | J2: 80 calls/day | K2: >15% conv rate | M2: 50+ connects
A3: DATE | B3: WEEK | C3: DAY | D3: CHANNEL | E3: EMAILS SENT | F3: OPEN RATE | G3: REPLY RATE | H3: POS REPLY % | I3: POS REPLIES | J3: CALLS MADE | K3: CONVOS | L3: ANSWER RATE | M3: LI CONNECTS | N3: LI REPLIES | O3: TOTAL TOUCHES | P3: NOTES
A4: WEEK 1 - 06 Jul to 10 Jul 2026
A5: 46209 | B5: W1 | C5: Mon | D5: Email / Calls / LI | E5: 0 | I5: 0 | J5: 0 | K5: 0 | M5: 0 | N5: 0 | F5: 0 | G5: 0 | H5: 0 | L5: =IF(J5=0,"",K5/J5) | O5: =IF(SUM(E5,J5,M5,N5)=0,"",SUM(E5,J5,M5,N5))
A6: 46210 | B6: W1 | C6: Tue | D6: Email / Calls / LI | E6: 0 | I6: 0 | J6: 0 | K6: 0 | M6: 0 | N6: 0 | F6: 0 | G6: 0 | H6: 0 | L6: =IF(J6=0,"",K6/J6) | O6: =IF(SUM(E6,J6,M6,N6)=0,"",SUM(E6,J6,M6,N6))
A7: 46211 | B7: W1 | C7: Wed | D7: Email / Calls / LI | E7: 0 | I7: 0 | J7: 0 | K7: 0 | M7: 0 | N7: 0 | F7: 0 | G7: 0 | H7: 0 | L7: =IF(J7=0,"",K7/J7) | O7: =IF(SUM(E7,J7,M7,N7)=0,"",SUM(E7,J7,M7,N7))
A8: 46212 | B8: W1 | C8: Thu | D8: Email / Calls / LI | E8: 0 | I8: 0 | J8: 0 | K8: 0 | M8: 0 | N8: 0 | F8: 0 | G8: 0 | H8: 0 | L8: =IF(J8=0,"",K8/J8) | O8: =IF(SUM(E8,J8,M8,N8)=0,"",SUM(E8,J8,M8,N8))
A9: 46213 | B9: W1 | C9: Fri | D9: Email / Calls / LI | E9: 0 | I9: 0 | J9: 0 | K9: 0 | M9: 0 | N9: 0 | F9: 0 | G9: 0 | H9: 0 | L9: =IF(J9=0,"",K9/J9) | O9: =IF(SUM(E9,J9,M9,N9)=0,"",SUM(E9,J9,M9,N9))
A10: WK 1 TOTAL | E10: =SUM(E5:E9) | I10: =SUM(I5:I9) | J10: =SUM(J5:J9) | K10: =SUM(K5:K9) | M10: =SUM(M5:M9) | N10: =SUM(N5:N9) | O10: =SUM(O5:O9) | F10: =IFERROR(AVERAGEIF(F5:F9,">0"),"") | G10: =IFERROR(AVERAGEIF(G5:G9,">0"),"") | H10: =IFERROR(AVERAGEIF(H5:H9,">0"),"") | L10: =IFERROR(AVERAGEIF(L5:L9,">0"),"")
A12: WEEK 2 - 13 Jul to 17 Jul 2026
A13: 46216 | B13: W2 | C13: Mon | D13: Email / Calls / LI | E13: 0 | I13: 0 | J13: 0 | K13: 0 | M13: 0 | N13: 0 | F13: 0 | G13: 0 | H13: 0 | L13: =IF(J13=0,"",K13/J13) | O13: =IF(SUM(E13,J13,M13,N13)=0,"",SUM(E13,J13,M13,N13))
A14: 46217 | B14: W2 | C14: Tue | D14: Email / Calls / LI | E14: 0 | I14: 0 | J14: 0 | K14: 0 | M14: 0 | N14: 0 | F14: 0 | G14: 0 | H14: 0 | L14: =IF(J14=0,"",K14/J14) | O14: =IF(SUM(E14,J14,M14,N14)=0,"",SUM(E14,J14,M14,N14))
A15: 46218 | B15: W2 | C15: Wed | D15: Email / Calls / LI | E15: 0 | I15: 0 | J15: 0 | K15: 0 | M15: 0 | N15: 0 | F15: 0 | G15: 0 | H15: 0 | L15: =IF(J15=0,"",K15/J15) | O15: =IF(SUM(E15,J15,M15,N15)=0,"",SUM(E15,J15,M15,N15))
A16: 46219 | B16: W2 | C16: Thu | D16: Email / Calls / LI | E16: 0 | I16: 0 | J16: 0 | K16: 0 | M16: 0 | N16: 0 | F16: 0 | G16: 0 | H16: 0 | L16: =IF(J16=0,"",K16/J16) | O16: =IF(SUM(E16,J16,M16,N16)=0,"",SUM(E16,J16,M16,N16))
A17: 46220 | B17: W2 | C17: Fri | D17: Email / Calls / LI | E17: 0 | I17: 0 | J17: 0 | K17: 0 | M17: 0 | N17: 0 | F17: 0 | G17: 0 | H17: 0 | L17: =IF(J17=0,"",K17/J17) | O17: =IF(SUM(E17,J17,M17,N17)=0,"",SUM(E17,J17,M17,N17))
A18: WK 2 TOTAL | E18: =SUM(E13:E17) | I18: =SUM(I13:I17) | J18: =SUM(J13:J17) | K18: =SUM(K13:K17) | M18: =SUM(M13:M17) | N18: =SUM(N13:N17) | O18: =SUM(O13:O17) | F18: =IFERROR(AVERAGEIF(F13:F17,">0"),"") | G18: =IFERROR(AVERAGEIF(G13:G17,">0"),"") | H18: =IFERROR(AVERAGEIF(H13:H17,">0"),"") | L18: =IFERROR(AVERAGEIF(L13:L17,">0"),"")
A20: WEEK 3 - 20 Jul to 24 Jul 2026
A21: 46223 | B21: W3 | C21: Mon | D21: Email / Calls / LI | E21: 0 | I21: 0 | J21: 0 | K21: 0 | M21: 0 | N21: 0 | F21: 0 | G21: 0 | H21: 0 | L21: =IF(J21=0,"",K21/J21) | O21: =IF(SUM(E21,J21,M21,N21)=0,"",SUM(E21,J21,M21,N21))
A22: 46224 | B22: W3 | C22: Tue | D22: Email / Calls / LI | E22: 0 | I22: 0 | J22: 0 | K22: 0 | M22: 0 | N22: 0 | F22: 0 | G22: 0 | H22: 0 | L22: =IF(J22=0,"",K22/J22) | O22: =IF(SUM(E22,J22,M22,N22)=0,"",SUM(E22,J22,M22,N22))
A23: 46225 | B23: W3 | C23: Wed | D23: Email / Calls / LI | E23: 0 | I23: 0 | J23: 0 | K23: 0 | M23: 0 | N23: 0 | F23: 0 | G23: 0 | H23: 0 | L23: =IF(J23=0,"",K23/J23) | O23: =IF(SUM(E23,J23,M23,N23)=0,"",SUM(E23,J23,M23,N23))
A24: 46226 | B24: W3 | C24: Thu | D24: Email / Calls / LI | E24: 0 | I24: 0 | J24: 0 | K24: 0 | M24: 0 | N24: 0 | F24: 0 | G24: 0 | H24: 0 | L24: =IF(J24=0,"",K24/J24) | O24: =IF(SUM(E24,J24,M24,N24)=0,"",SUM(E24,J24,M24,N24))
A25: 46227 | B25: W3 | C25: Fri | D25: Email / Calls / LI | E25: 0 | I25: 0 | J25: 0 | K25: 0 | M25: 0 | N25: 0 | F25: 0 | G25: 0 | H25: 0 | L25: =IF(J25=0,"",K25/J25) | O25: =IF(SUM(E25,J25,M25,N25)=0,"",SUM(E25,J25,M25,N25))
A26: WK 3 TOTAL | E26: =SUM(E21:E25) | I26: =SUM(I21:I25) | J26: =SUM(J21:J25) | K26: =SUM(K21:K25) | M26: =SUM(M21:M25) | N26: =SUM(N21:N25) | O26: =SUM(O21:O25) | F26: =IFERROR(AVERAGEIF(F21:F25,">0"),"") | G26: =IFERROR(AVERAGEIF(G21:G25,">0"),"") | H26: =IFERROR(AVERAGEIF(H21:H25,">0"),"") | L26: =IFERROR(AVERAGEIF(L21:L25,">0"),"")
A28: WEEK 4 - 27 Jul to 31 Jul 2026
A29: 46230 | B29: W4 | C29: Mon | D29: Email / Calls / LI | E29: 0 | I29: 0 | J29: 0 | K29: 0 | M29: 0 | N29: 0 | F29: 0 | G29: 0 | H29: 0 | L29: =IF(J29=0,"",K29/J29) | O29: =IF(SUM(E29,J29,M29,N29)=0,"",SUM(E29,J29,M29,N29))
A30: 46231 | B30: W4 | C30: Tue | D30: Email / Calls / LI | E30: 0 | I30: 0 | J30: 0 | K30: 0 | M30: 0 | N30: 0 | F30: 0 | G30: 0 | H30: 0 | L30: =IF(J30=0,"",K30/J30) | O30: =IF(SUM(E30,J30,M30,N30)=0,"",SUM(E30,J30,M30,N30))
A31: 46232 | B31: W4 | C31: Wed | D31: Email / Calls / LI | E31: 0 | I31: 0 | J31: 0 | K31: 0 | M31: 0 | N31: 0 | F31: 0 | G31: 0 | H31: 0 | L31: =IF(J31=0,"",K31/J31) | O31: =IF(SUM(E31,J31,M31,N31)=0,"",SUM(E31,J31,M31,N31))
A32: 46233 | B32: W4 | C32: Thu | D32: Email / Calls / LI | E32: 0 | I32: 0 | J32: 0 | K32: 0 | M32: 0 | N32: 0 | F32: 0 | G32: 0 | H32: 0 | L32: =IF(J32=0,"",K32/J32) | O32: =IF(SUM(E32,J32,M32,N32)=0,"",SUM(E32,J32,M32,N32))
A33: 46234 | B33: W4 | C33: Fri | D33: Email / Calls / LI | E33: 0 | I33: 0 | J33: 0 | K33: 0 | M33: 0 | N33: 0 | F33: 0 | G33: 0 | H33: 0 | L33: =IF(J33=0,"",K33/J33) | O33: =IF(SUM(E33,J33,M33,N33)=0,"",SUM(E33,J33,M33,N33))
A34: WK 4 TOTAL | E34: =SUM(E29:E33) | I34: =SUM(I29:I33) | J34: =SUM(J29:J33) | K34: =SUM(K29:K33) | M34: =SUM(M29:M33) | N34: =SUM(N29:N33) | O34: =SUM(O29:O33) | F34: =IFERROR(AVERAGEIF(F29:F33,">0"),"") | G34: =IFERROR(AVERAGEIF(G29:G33,">0"),"") | H34: =IFERROR(AVERAGEIF(H29:H33,">0"),"") | L34: =IFERROR(AVERAGEIF(L29:L33,">0"),"")
A36: WEEK 5 - 03 Aug to 07 Aug 2026
A37: 46237 | B37: W5 | C37: Mon | D37: Email / Calls / LI | E37: 0 | I37: 0 | J37: 0 | K37: 0 | M37: 0 | N37: 0 | F37: 0 | G37: 0 | H37: 0 | L37: =IF(J37=0,"",K37/J37) | O37: =IF(SUM(E37,J37,M37,N37)=0,"",SUM(E37,J37,M37,N37))
A38: 46238 | B38: W5 | C38: Tue | D38: Email / Calls / LI | E38: 0 | I38: 0 | J38: 0 | K38: 0 | M38: 0 | N38: 0 | F38: 0 | G38: 0 | H38: 0 | L38: =IF(J38=0,"",K38/J38) | O38: =IF(SUM(E38,J38,M38,N38)=0,"",SUM(E38,J38,M38,N38))
A39: 46239 | B39: W5 | C39: Wed | D39: Email / Calls / LI | E39: 0 | I39: 0 | J39: 0 | K39: 0 | M39: 0 | N39: 0 | F39: 0 | G39: 0 | H39: 0 | L39: =IF(J39=0,"",K39/J39) | O39: =IF(SUM(E39,J39,M39,N39)=0,"",SUM(E39,J39,M39,N39))
A40: 46240 | B40: W5 | C40: Thu | D40: Email / Calls / LI | E40: 0 | I40: 0 | J40: 0 | K40: 0 | M40: 0 | N40: 0 | F40: 0 | G40: 0 | H40: 0 | L40: =IF(J40=0,"",K40/J40) | O40: =IF(SUM(E40,J40,M40,N40)=0,"",SUM(E40,J40,M40,N40))
A41: 46241 | B41: W5 | C41: Fri | D41: Email / Calls / LI | E41: 0 | I41: 0 | J41: 0 | K41: 0 | M41: 0 | N41: 0 | F41: 0 | G41: 0 | H41: 0 | L41: =IF(J41=0,"",K41/J41) | O41: =IF(SUM(E41,J41,M41,N41)=0,"",SUM(E41,J41,M41,N41))
A42: WK 5 TOTAL | E42: =SUM(E37:E41) | I42: =SUM(I37:I41) | J42: =SUM(J37:J41) | K42: =SUM(K37:K41) | M42: =SUM(M37:M41) | N42: =SUM(N37:N41) | O42: =SUM(O37:O41) | F42: =IFERROR(AVERAGEIF(F37:F41,">0"),"") | G42: =IFERROR(AVERAGEIF(G37:G41,">0"),"") | H42: =IFERROR(AVERAGEIF(H37:H41,">0"),"") | L42: =IFERROR(AVERAGEIF(L37:L41,">0"),"")
A44: WEEK 6 - 10 Aug to 14 Aug 2026
A45: 46244 | B45: W6 | C45: Mon | D45: Email / Calls / LI | E45: 0 | I45: 0 | J45: 0 | K45: 0 | M45: 0 | N45: 0 | F45: 0 | G45: 0 | H45: 0 | L45: =IF(J45=0,"",K45/J45) | O45: =IF(SUM(E45,J45,M45,N45)=0,"",SUM(E45,J45,M45,N45))
...

Sheet 2 - Conversion
A1: TARGETS 300+ emails/wk >35% open >5% reply >3% pos 80 calls/day >15% conv rate 50+ connects
A2: TARGETS | E2: >10% | G2: >70% | I2: >50% | O2: >30%
A3: WEEK | B3: WEEK START | C3: POS REPLIES | D3: MTGS BOOKED | E3: REPLY-BOOK % | F3: MTGS HELD | G3: SHOW RATE | H3: NO-SHOWS | I3: RECOVERED | J3: RECOVERY % | K3: DISCO HELD | L3: QUAL 4.0+ | M3: QUAL RATE | N3: PROPOSALS | O3: WON | P3: WIN RATE | Q3: NEW MRR USD | R3: NOTES
A4: W1 | B4: 46210 | C4: 0 | D4: 0 | F4: 0 | H4: 0 | I4: 0 | K4: 0 | L4: 0 | N4: 0 | O4: 0 | Q4: 0 | E4: =IF(C4=0,"",D4/C4) | G4: =IF(D4=0,"",F4/D4) | J4: =IF(H4=0,"",I4/H4) | M4: =IF(K4=0,"",L4/K4) | P4: =IF(N4=0,"",O4/N4)
A5: W2 | B5: 46217 | C5: 0 | D5: 0 | F5: 0 | H5: 0 | I5: 0 | K5: 0 | L5: 0 | N5: 0 | O5: 0 | Q5: 0 | E5: =IF(C5=0,"",D5/C5) | G5: =IF(D5=0,"",F5/D5) | J5: =IF(H5=0,"",I5/H5) | M5: =IF(K5=0,"",L5/K5) | P5: =IF(N5=0,"",O5/N5)
A6: W3 | B6: 46224 | C6: 0 | D6: 0 | F6: 0 | H6: 0 | I6: 0 | K6: 0 | L6: 0 | N6: 0 | O6: 0 | Q6: 0 | E6: =IF(C6=0,"",D6/C6) | G6: =IF(D6=0,"",F6/D6) | J6: =IF(H6=0,"",I6/H6) | M6: =IF(K6=0,"",L6/K6) | P6: =IF(N6=0,"",O6/N6)
A7: W4 | B7: 46231 | C7: 0 | D7: 0 | F7: 0 | H7: 0 | I7: 0 | K7: 0 | L7: 0 | N7: 0 | O7: 0 | Q7: 0 | E7: =IF(C7=0,"",D7/C7) | G7: =IF(D7=0,"",F7/D7) | J7: =IF(H7=0,"",I7/H7) | M7: =IF(K7=0,"",L7/K7) | P7: =IF(N7=0,"",O7/N7)
A8: W5 | B8: 46238 | C8: 0 | D8: 0 | F8: 0 | H8: 0 | I8: 0 | K8: 0 | L8: 0 | N8: 0 | O8: 0 | Q8: 0 | E8: =IF(C8=0,"",D8/C8) | G8: =IF(D8=0,"",F8/D8) | J8: =IF(H8=0,"",I8/H8) | M8: =IF(K8=0,"",L8/K8) | P8: =IF(N8=0,"",O8/N8)
A9: W6 | B9: 46245 | C9: 0 | D9: 0 | F9: 0 | H9: 0 | I9: 0 | K9: 0 | L9: 0 | N9: 0 | O9: 0 | Q9: 0 | E9: =IF(C9=0,"",D9/C9) | G9: =IF(D9=0,"",F9/D9) | J9: =IF(H9=0,"",I9/H9) | M9: =IF(K9=0,"",L9/K9) | P9: =IF(N9=0,"",O9/N9)
A10: W7 | B10: 46252 | C10: 0 | D10: 0 | F10: 0 | H10: 0 | I10: 0 | K10: 0 | L10: 0 | N10: 0 | O10: 0 | Q10: 0 | E10: =IF(C10=0,"",D10/C10) | G10: =IF(D10=0,"",F10/D10) | J10: =IF(H10=0,"",I10/H10) | M10: =IF(K10=0,"",L10/K10) | P10: =IF(N10=0,"",O10/N10)
A11: W8 | B11: 46259 | C11: 0 | D11: 0 | F11: 0 | H11: 0 | I11: 0 | K11: 0 | L11: 0 | N11: 0 | O11: 0 | Q11: 0 | E11: =IF(C11=0,"",D11/C11) | G11: =IF(D11=0,"",F11/D11) | J11: =IF(H11=0,"",I11/H11) | M11: =IF(K11=0,"",L11/K11) | P11: =IF(N11=0,"",O11/N11)
A12: W9 | B12: 46266 | C12: 0 | D12: 0 | F12: 0 | H12: 0 | I12: 0 | K12: 0 | L12: 0 | N12: 0 | O12: 0 | Q12: 0 | E12: =IF(C12=0,"",D12/C12) | G12: =IF(D12=0,"",F12/D12) | J12: =IF(H12=0,"",I12/H12) | M12: =IF(K12=0,"",L12/K12) | P12: =IF(N12=0,"",O12/N12)
A13: W10 | B13: 46273 | C13: 0 | D13: 0 | F13: 0 | H13: 0 | I13: 0 | K13: 0 | L13: 0 | N13: 0 | O13: 0 | Q13: 0 | E13: =IF(C13=0,"",D13/C13) | G13: =IF(D13=0,"",F13/D13) | J13: =IF(H13=0,"",I13/H13) | M13: =IF(K13=0,"",L13/K13) | P13: =IF(N13=0,"",O13/N13)
A14: W11 | B14: 46280 | C14: 0 | D14: 0 | F14: 0 | H14: 0 | I14: 0 | K14: 0 | L14: 0 | N14: 0 | O14: 0 | Q14: 0 | E14: =IF(C14=0,"",D14/C14) | G14: =IF(D14=0,"",F14/D14) | J14: =IF(H14=0,"",I14/H14) | M14: =IF(K14=0,"",L14/K14) | P14: =IF(N14=0,"",O14/N14)
A15: W12 | B15: 46287 | C15: 0 | D15: 0 | F15: 0 | H15: 0 | I15: 0 | K15: 0 | L15: 0 | N15: 0 | O15: 0 | Q15: 0 | E15: =IF(C15=0,"",D15/C15) | G15: =IF(D15=0,"",F15/D15) | J15: =IF(H15=0,"",I15/H15) | M15: =IF(K15=0,"",L15/K15) | P15: =IF(N15=0,"",O15/N15)
A16: 12-WK TOTAL / AVG | C16: =SUM(C4:C15) | D16: =SUM(D4:D15) | F16: =SUM(F4:F15) | H16: =SUM(H4:H15) | I16: =SUM(I4:I15) | K16: =SUM(K4:K15) | L16: =SUM(L4:L15) | N16: =SUM(N4:N15) | O16: =SUM(O4:O15) | Q16: =SUM(Q4:Q15) | E16: =IFERROR(AVERAGEIF(E4:E15,">0"),"") | G16: =IFERROR(AVERAGEIF(G4:G15,">0"),"") | J16: =IFERROR(AVERAGEIF(J4:J15,">0"),"") | M16: =IFERROR(AVERAGEIF(M4:M15,">0"),"") | P16: =IFERROR(AVERAGEIF(P4:P15,">0"),"")

Sheet 3 - Pipeline
A1: ALIF AGENCY - PIPELINE VALUE - Weekly Stage Breakdown - All values USD
A2: WEEK | B2: WEEK START | C2: TOTAL PIPELINE | D2: POS REPLY STAGE | E2: MTG BOOKED | F2: MTG HELD | G2: PROPOSAL SENT | H2: VERBAL YES | I2: AVG DEAL USD | J2: AVG AGE DAYS | K2: STALLED 7D+ | L2: DEALS WON | M2: DEALS LOST | N2: NEW MRR USD | O2: CUMUL MRR USD
A3: W1 | B3: 46210 | D3: 0 | E3: 0 | F3: 0 | G3: 0 | H3: 0 | I3: 0 | J3: 0 | K3: 0 | L3: 0 | M3: 0 | N3: 0 | C3: =SUM(D3:H3) | O3: =N3
A4: W2 | B4: 46217 | D4: 0 | E4: 0 | F4: 0 | G4: 0 | H4: 0 | I4: 0 | J4: 0 | K4: 0 | L4: 0 | M4: 0 | N4: 0 | C4: =SUM(D4:H4) | O4: =O3+N4
A5: W3 | B5: 46224 | D5: 0 | E5: 0 | F5: 0 | G5: 0 | H5: 0 | I5: 0 | J5: 0 | K5: 0 | L5: 0 | M5: 0 | N5: 0 | C5: =SUM(D5:H5) | O5: =O4+N5
A6: W4 | B6: 46231 | D6: 0 | E6: 0 | F6: 0 | G6: 0 | H6: 0 | I6: 0 | J6: 0 | K6: 0 | L6: 0 | M6: 0 | N6: 0 | C6: =SUM(D6:H6) | O6: =O5+N6
A7: W5 | B7: 46238 | D7: 0 | E7: 0 | F7: 0 | G7: 0 | H7: 0 | I7: 0 | J7: 0 | K7: 0 | L7: 0 | M7: 0 | N7: 0 | C7: =SUM(D7:H7) | O7: =O6+N7
A8: W6 | B8: 46245 | D8: 0 | E8: 0 | F8: 0 | G8: 0 | H8: 0 | I8: 0 | J8: 0 | K8: 0 | L8: 0 | M8: 0 | N8: 0 | C8: =SUM(D8:H8) | O8: =O7+N8
A9: W7 | B9: 46252 | D9: 0 | E9: 0 | F9: 0 | G9: 0 | H9: 0 | I9: 0 | J9: 0 | K9: 0 | L9: 0 | M9: 0 | N9: 0 | C9: =SUM(D9:H9) | O9: =O8+N9
A10: W8 | B10: 46259 | D10: 0 | E10: 0 | F10: 0 | G10: 0 | H10: 0 | I10: 0 | J10: 0 | K10: 0 | L10: 0 | M10: 0 | N10: 0 | C10: =SUM(D10:H10) | O10: =O9+N10
A11: W9 | B11: 46266 | D11: 0 | E11: 0 | F11: 0 | G11: 0 | H11: 0 | I11: 0 | J11: 0 | K11: 0 | L11: 0 | M11: 0 | N11: 0 | C11: =SUM(D11:H11) | O11: =O10+N11
A12: W10 | B12: 46273 | D12: 0 | E12: 0 | F12: 0 | G12: 0 | H12: 0 | I12: 0 | J12: 0 | K12: 0 | L12: 0 | M12: 0 | N12: 0 | C12: =SUM(D12:H12) | O12: =O11+N12
A13: W11 | B13: 46280 | D13: 0 | E13: 0 | F13: 0 | G13: 0 | H13: 0 | I13: 0 | J13: 0 | K13: 0 | L13: 0 | M13: 0 | N13: 0 | C13: =SUM(D13:H13) | O13: =O12+N13
A14: W12 | B14: 46287 | D14: 0 | E14: 0 | F14: 0 | G14: 0 | H14: 0 | I14: 0 | J14: 0 | K14: 0 | L14: 0 | M14: 0 | N14: 0 | C14: =SUM(D14:H14) | O14: =O13+N14
A15: 12-WEEK SUMMARY | K15: =SUM(K3:K14) | L15: =SUM(L3:L14) | M15: =SUM(M3:M14) | N15: =SUM(N3:N14) | O15: =O14

Sheet Dashboard
A1: ALIF AGENCY - HEAD OF SALES DASHBOARD - All values USD
A2: TARGETS >10% >70% >50% >30%
A4: OUTREACH - 12-WEEK TOTALS
A5: Total Positive Replies | B5: ='2 - Conversion'!C16 | C5: All channels combined
A6: Total Meetings Booked | B6: ='2 - Conversion'!D16 | C6: Target: 60+ over 12 weeks
A7: Total Proposals Sent | B7: ='2 - Conversion'!N16
A9: CONVERSION - 12-WEEK AVERAGES
A10: Reply to Booking Rate | B10: ='2 - Conversion'!E16 | C10: TARGET 10% | Baseline 0.2% - THE ONE METRIC
A11: Show Rate | B11: ='2 - Conversion'!G16 | C11: Target 70%
A12: No-Show Recovery | B12: ='2 - Conversion'!J16 | C12: Target 50%
A13: Qualification Rate | B13: ='2 - Conversion'!M16 | C13: Target 80%
A14: Proposal Win Rate | B14: ='2 - Conversion'!P16 | C14: Target 30%
A16: PIPELINE - 12-WEEK TOTALS (USD)
A17: Deals Won | B17: ='3 - Pipeline'!L15
A18: Deals Lost | B18: ='3 - Pipeline'!M15
A19: Total New MRR Added | B19: ='3 - Pipeline'!N15 | C19: USD
A20: Cumulative MRR Week 12 | B20: ='3 - Pipeline'!O14 | C20: USD - running balance
A22: THE 5 FUNNEL RATIOS - REVIEW EVERY MONDAY
A23: 1. Positive Reply to Booking | B23: ='2 - Conversion'!E16 | C23: Target 10%
A24: 2. Booked to Held | B24: ='2 - Conversion'!G16 | C24: Target 70%
A25: 3. Held to Qualified | B25: ='2 - Conversion'!M16 | C25: Target 80%
A26: 4. Qualified to Proposal | C26: Aim 90%+
A27: 5. Proposal to Won | B27: ='2 - Conversion'!P16 | C27: Target 30%
A29: HOW TO USE
A30: Sheet 1 - Outreach: Fill daily Mon-Fri. Cols F G H = enter as decimals (0.35 = 35%). L and O auto-calculate.
A31: Sheet 2 - Conversion: Fill each Monday with previous week totals. Rate columns (E G J M P) auto-calculate.
A32: Sheet 3 - Pipeline: Enter USD deal values by stage each Monday. Cumulative MRR (col O) chains automatically.
A33: All currency in USD. Convert at prevailing rate before entry regardless of deal geography.
A34: THE ONE METRIC to move first: Reply-to-Booking % (Sheet 2 col E). Baseline 0.2%. Target 10%+.
